<?xml version="1.0" ?>
<!-- =================================================================================== -->
<!-- |    This document was autogenerated by xacro from /root/ros_ws/src/husky/husky_description/urdf/husky.urdf.xacro | -->
<!-- |    EDITING THIS FILE BY HAND IS NOT RECOMMENDED                                 | -->
<!-- =================================================================================== -->
<!--
Software License Agreement (BSD)

\file      husky.urdf.xacro
\authors   Paul Bovbel <pbovbel@clearpathrobotics.com>, Devon Ash <dash@clearpathrobotics.com>
\copyright Copyright (c) 2015, Clearpath Robotics, Inc., All rights reserved.

Redistribution and use in source and binary forms, with or without modification, are permitted provided that
the following conditions are met:
 * Redistributions of source code must retain the above copyright notice, this list of conditions and the
   following disclaimer.
 * Redistributions in binary form must reproduce the above copyright notice, this list of conditions and the
   following disclaimer in the documentation and/or other materials provided with the distribution.
 * Neither the name of Clearpath Robotics nor the names of its contributors may be used to endorse or promote
   products derived from this software without specific prior written permission.

THIS SOFTWARE IS PROVIDED BY THE COPYRIGHT HOLDERS AND CONTRIBUTORS "AS IS" AND ANY EXPRESS OR IMPLIED WAR-
RANTIES, INCLUDING, BUT NOT LIMITED TO, THE IMPLIED WARRANTIES OF MERCHANTABILITY AND FITNESS FOR A PARTICULAR
PURPOSE ARE DISCLAIMED. IN NO EVENT SHALL THE COPYRIGHT HOLDER OR CONTRIBUTORS BE LIABLE FOR ANY DIRECT, IN-
DIRECT, INCIDENTAL, SPECIAL, EXEMPLARY, OR CONSEQUENTIAL DAMAGES (INCLUDING, BUT NOT LIMITED TO, PROCUREMENT
OF SUBSTITUTE GOODS OR SERVICES; LOSS OF USE, DATA, OR PROFITS; OR BUSINESS INTERRUPTION) HOWEVER CAUSED AND
ON ANY THEORY OF LIABILITY, WHETHER IN CONTRACT, STRICT LIABILITY, OR TORT (INCLUDING NEGLIGENCE OR OTHERWISE)
ARISING IN ANY WAY OUT OF THE USE OF THIS SOFTWARE, EVEN IF ADVISED OF THE POSSIBILITY OF SUCH DAMAGE.
-->
<robot name="husky">
    <material name="dark_grey">
        <color rgba="0.2 0.2 0.2 1.0" />
    </material>
    <material name="medium_grey">
        <color rgba="0.6 0.6 0.6 1.0" />
    </material>
    <material name="light_grey">
        <color rgba="0.8 0.8 0.8 1.0" />
    </material>
    <material name="yellow">
        <color rgba="0.8 0.8 0.0 1.0" />
    </material>
    <material name="black">
        <color rgba="0.15 0.15 0.15 1.0" />
    </material>
    <material name="white">
        <color rgba="1.0 1.0 1.0 1.0" />
    </material>
    <material name="red">
        <color rgba="1.0 0.0 0.0 1.0" />
    </material>
    <!-- Base link is the center of the robot's bottom plate -->
    <link name="base_link">
        <visual>
            <origin rpy="0 0 0" xyz="0 0 0" />
            <geometry>
                <mesh filename="package://husky_description/meshes/base_link.dae" />
            </geometry>
        </visual>
        <collision>
            <origin rpy="0 0 0" xyz="0.0 0 0.061875" />
            <geometry>
                <box size="0.9874 0.5709 0.12375" />
            </geometry>
        </collision>
        <collision>
            <origin rpy="0 0 0" xyz="0 0 0.17562499999999998" />
            <geometry>
                <box size="0.7899200000000001 0.5709 0.10375" />
            </geometry>
        </collision>
        <inertial>
            <mass value="0.1" />
            <origin xyz="0 0 0" rpy="0 0 0" />
            <inertia ixx="0.03" iyy="0.03" izz="0.03" ixy="0.0" ixz="0.0" iyz="0.0" />
        </inertial>
    </link>
    <!-- Base footprint is on the ground under the robot -->
    <link name="base_footprint" />
    <joint name="base_footprint_joint" type="fixed">
        <origin rpy="0 0 0" xyz="0 0 -0.13228" />
        <parent link="base_link" />
        <child link="base_footprint" />
    </joint>
    <!-- Inertial link stores the robot's inertial information -->
    <link name="inertial_link">
        <inertial>
            <mass value="46.034" />
            <origin xyz="-0.00065 -0.085 0.062" />
            <inertia ixx="0.6022" ixy="-0.02364" ixz="-0.1197" iyy="1.7386" iyz="-0.001544" izz="2.0296" />
        </inertial>
    </link>
    <joint name="inertial_joint" type="fixed">
        <origin rpy="0 0 0" xyz="0 0 0" />
        <parent link="base_link" />
        <child link="inertial_link" />
    </joint>
    <link name="front_left_wheel_link">
        <inertial>
            <mass value="2.637" />
            <origin xyz="0 0 0" rpy="0 0 0" />
            <inertia ixx="0.02467" ixy="0" ixz="0" iyy="0.04411" iyz="0" izz="0.02467" />
        </inertial>
        <visual>
            <origin rpy="0 0 0" xyz="0 0 0" />
            <geometry>
                <mesh filename="package://husky_description/meshes/wheel.dae" />
            </geometry>
        </visual>
        <collision>
            <origin rpy="1.570795 0 0" xyz="0 0 0" />
            <geometry>
                <cylinder length="0.1143" radius="0.1651" />
            </geometry>
        </collision>
    </link>
    <gazebo reference="front_left_wheel_link">
        <mu1 value="1.0" />
        <mu2 value="1.0" />
        <kp value="10000000.0" />
        <kd value="1.0" />
        <fdir1 value="1 0 0" />
        <plugin name="gazebo_ros_control">
            <robotNamespace>/</robotNamespace>
        </plugin>
    </gazebo>
    <joint name="front_left_wheel" type="continuous">
        <parent link="base_link" />
        <child link="front_left_wheel_link" />
        <origin rpy="0 0 0" xyz="0.256 0.2854 0.03282" />
        <axis rpy="0 0 0" xyz="0 1 0" />
    </joint>
    <transmission name="front_left_wheel_trans" type="SimpleTransmission">
        <type>transmission_interface/SimpleTransmission</type>
        <actuator name="front_left_wheel_motor">
            <mechanicalReduction>1</mechanicalReduction>
            <hardwareInterface>hardware_interface/EffortJointInterface</hardwareInterface>
        </actuator>
        <joint name="front_left_wheel">
            <hardwareInterface>hardware_interface/VelocityJointInterface</hardwareInterface>
        </joint>
    </transmission>
    <link name="front_right_wheel_link">
        <inertial>
            <mass value="2.637" />
            <origin xyz="0 0 0" rpy="0 0 0" />
            <inertia ixx="0.02467" ixy="0" ixz="0" iyy="0.04411" iyz="0" izz="0.02467" />
        </inertial>
        <visual>
            <origin rpy="0 0 0" xyz="0 0 0" />
            <geometry>
                <mesh filename="package://husky_description/meshes/wheel.dae" />
            </geometry>
        </visual>
        <collision>
            <origin rpy="1.570795 0 0" xyz="0 0 0" />
            <geometry>
                <cylinder length="0.1143" radius="0.1651" />
            </geometry>
        </collision>
    </link>
    <gazebo reference="front_right_wheel_link">
        <mu1 value="1.0" />
        <mu2 value="1.0" />
        <kp value="10000000.0" />
        <kd value="1.0" />
        <fdir1 value="1 0 0" />
    </gazebo>
    <joint name="front_right_wheel" type="continuous">
        <parent link="base_link" />
        <child link="front_right_wheel_link" />
        <origin rpy="0 0 0" xyz="0.256 -0.2854 0.03282" />
        <axis rpy="0 0 0" xyz="0 1 0" />
    </joint>
    <transmission name="front_right_wheel_trans" type="SimpleTransmission">
        <type>transmission_interface/SimpleTransmission</type>
        <actuator name="front_right_wheel_motor">
            <mechanicalReduction>1</mechanicalReduction>
            <hardwareInterface>hardware_interface/EffortJointInterface</hardwareInterface>
        </actuator>
        <joint name="front_right_wheel">
            <hardwareInterface>hardware_interface/VelocityJointInterface</hardwareInterface>
        </joint>
    </transmission>
    <link name="rear_left_wheel_link">
        <inertial>
            <mass value="2.637" />
            <origin xyz="0 0 0" rpy="0 0 0" />
            <inertia ixx="0.02467" ixy="0" ixz="0" iyy="0.04411" iyz="0" izz="0.02467" />
        </inertial>
        <visual>
            <origin rpy="0 0 0" xyz="0 0 0" />
            <geometry>
                <mesh filename="package://husky_description/meshes/wheel.dae" />
            </geometry>
        </visual>
        <collision>
            <origin rpy="1.570795 0 0" xyz="0 0 0" />
            <geometry>
                <cylinder length="0.1143" radius="0.1651" />
            </geometry>
        </collision>
    </link>
    <gazebo reference="rear_left_wheel_link">
        <mu1 value="1.0" />
        <mu2 value="1.0" />
        <kp value="10000000.0" />
        <kd value="1.0" />
        <fdir1 value="1 0 0" />
    </gazebo>
    <joint name="rear_left_wheel" type="continuous">
        <parent link="base_link" />
        <child link="rear_left_wheel_link" />
        <origin rpy="0 0 0" xyz="-0.256 0.2854 0.03282" />
        <axis rpy="0 0 0" xyz="0 1 0" />
    </joint>
    <transmission name="rear_left_wheel_trans" type="SimpleTransmission">
        <type>transmission_interface/SimpleTransmission</type>
        <actuator name="rear_left_wheel_motor">
            <mechanicalReduction>1</mechanicalReduction>
            <hardwareInterface>hardware_interface/EffortJointInterface</hardwareInterface>
        </actuator>
        <joint name="rear_left_wheel">
            <hardwareInterface>hardware_interface/VelocityJointInterface</hardwareInterface>
        </joint>
    </transmission>
    <link name="rear_right_wheel_link">
        <inertial>
            <mass value="2.637" />
            <origin xyz="0 0 0" rpy="0 0 0" />
            <inertia ixx="0.02467" ixy="0" ixz="0" iyy="0.04411" iyz="0" izz="0.02467" />
        </inertial>
        <visual>
            <origin rpy="0 0 0" xyz="0 0 0" />
            <geometry>
                <mesh filename="package://husky_description/meshes/wheel.dae" />
            </geometry>
        </visual>
        <collision>
            <origin rpy="1.570795 0 0" xyz="0 0 0" />
            <geometry>
                <cylinder length="0.1143" radius="0.1651" />
            </geometry>
        </collision>
    </link>
    <gazebo reference="rear_right_wheel_link">
        <mu1 value="1.0" />
        <mu2 value="1.0" />
        <kp value="10000000.0" />
        <kd value="1.0" />
        <fdir1 value="1 0 0" />
    </gazebo>
    <joint name="rear_right_wheel" type="continuous">
        <parent link="base_link" />
        <child link="rear_right_wheel_link" />
        <origin rpy="0 0 0" xyz="-0.256 -0.2854 0.03282" />
        <axis rpy="0 0 0" xyz="0 1 0" />
    </joint>
    <transmission name="rear_right_wheel_trans" type="SimpleTransmission">
        <type>transmission_interface/SimpleTransmission</type>
        <actuator name="rear_right_wheel_motor">
            <mechanicalReduction>1</mechanicalReduction>
            <hardwareInterface>hardware_interface/EffortJointInterface</hardwareInterface>
        </actuator>
        <joint name="rear_right_wheel">
            <hardwareInterface>hardware_interface/VelocityJointInterface</hardwareInterface>
        </joint>
    </transmission>
    <!--
      CHASSIS: Spawn and attach default chassis.
               Currently, no customization available.
    -->
    <!-- Spawn Husky chassis -->
    <link name="top_chassis_link">
        <visual>
            <origin rpy="0 0 0" xyz="0 0 0" />
            <geometry>
                <mesh filename="package://husky_description/meshes/top_chassis.dae" />
            </geometry>
        </visual>
    </link>
    <!-- Attach chassis to the robot -->
    <joint name="top_chassis_joint" type="fixed">
        <parent link="base_link" />
        <child link="top_chassis_link" />
    </joint>
    <link name="front_bumper_link">
        <visual>
            <geometry>
                <mesh filename="package://husky_description/meshes/bumper.dae" />
            </geometry>
        </visual>
    </link>
    <!-- Attach front bumper -->
    <joint name="front_bumper" type="fixed">
        <origin rpy="0 0 0" xyz="0.48 0 0.091" />
        <parent link="base_link" />
        <child link="front_bumper_link" />
    </joint>
    <link name="rear_bumper_link">
        <visual>
            <geometry>
                <mesh filename="package://husky_description/meshes/bumper.dae" />
            </geometry>
        </visual>
    </link>
    <!-- Attach rear bumper -->
    <joint name="rear_bumper" type="fixed">
        <origin rpy="0 0 3.14159" xyz="-0.48 0 0.091" />
        <parent link="base_link" />
        <child link="rear_bumper_link" />
    </joint>
    <!-- Spawn user rails -->
    <link name="user_rail_link">
        <visual>
            <geometry>
                <mesh filename="package://husky_description/meshes/user_rail.dae" />
            </geometry>
        </visual>
    </link>
    <!-- Attach user rails to base link -->
    <joint name="user_rail" type="fixed">
        <origin rpy="0 0 0" xyz="0.272 0 0.245" />
        <parent link="base_link" />
        <child link="user_rail_link" />
    </joint>
    <!-- Spawn default top plate -->
    <link name="top_plate_link">
        <visual>
            <origin rpy="0 0 0" xyz="0 0 0" />
            <geometry>
                <mesh filename="package://husky_description/meshes/top_plate.dae" />
            </geometry>
        </visual>
        <collision>
            <origin rpy="0 0 0" xyz="0 0 0" />
            <geometry>
                <mesh filename="package://husky_description/meshes/top_plate.stl" />
            </geometry>
        </collision>
        <inertial>
            <mass value="0.1" />
            <origin xyz="0 0 0" rpy="0 0 0" />
            <inertia ixx="0.03" iyy="0.03" izz="0.03" ixy="0.0" ixz="0.0" iyz="0.0" />
        </inertial>
    </link>
    <!-- Attach default top plate -->
    <joint name="top_plate_joint" type="fixed">
        <parent link="base_link" />
        <child link="top_plate_link" />
        <origin rpy="0 0 0" xyz="0.0812 0 0.245" />
    </joint>
    <!-- Default top plate front link -->
    <link name="top_plate_front_link" />
    <joint name="top_plate_front_joint" type="fixed">
        <parent link="top_plate_link" />
        <child link="top_plate_front_link" />
        <origin rpy="0 0 0" xyz="0.36367 0 0.00639" />
    </joint>
    <!-- Default top plate rear link-->
    <link name="top_plate_rear_link" />
    <joint name="top_plate_rear_joint" type="fixed">
        <parent link="top_plate_link" />
        <child link="top_plate_rear_link" />
        <origin rpy="0 0 0" xyz="-0.36633 0 0.00639" />
    </joint>
    <link name="sensor_arch_base_link" />
    <!-- Spawn the sensor arch link -->
    <link name="sensor_arch_mount_link">
        <origin rpy="0 0 0" xyz="0 0 0" />
        <visual>
            <geometry>
                <mesh filename="package://husky_description/meshes/accessories/510_mm_sensor_arch.dae" />
            </geometry>
        </visual>
        <collision>
            <origin rpy="0 0 0" xyz="0 0 0" />
            <geometry>
                <mesh filename="package://husky_description/meshes/accessories/510_mm_sensor_arch.dae" />
            </geometry>
        </collision>
        <inertial>
            <mass value="0.1" />
            <origin xyz="0 0 0" rpy="0 0 0" />
            <inertia ixx="0.03" iyy="0.03" izz="0.03" ixy="0.0" ixz="0.0" iyz="0.0" />
        </inertial>
    </link>
    <joint name="sensor_arch_base_link_joint" type="fixed">
        <parent link="top_plate_link" />
        <child link="sensor_arch_base_link" />
        <origin rpy="0 0 0" xyz="0 0 0" />
    </joint>
    <!-- Attach the sensor arch to the top plate -->
    <joint name="sensor_arch_mount" type="fixed">
        <parent link="sensor_arch_base_link" />
        <child link="sensor_arch_mount_link" />
        <origin rpy="0 0 0" xyz="0 0 0.51" />
    </joint>
    <!--
      IMU Link: Standard location to add an IMU (i.e. UM7 or Microstrain)
  -->
    <link name="imu_link" />
    <joint name="imu_joint" type="fixed">
        <origin rpy="0 -1.5708 3.1416" xyz="0.19 0 0.149" />
        <parent link="base_link" />
        <child link="imu_link" />
    </joint>
    <gazebo reference="imu_link" />
    <gazebo>
        <plugin filename="libgazebo_ros_control.so" name="gazebo_ros_control">
            <robotNamespace>/</robotNamespace>
            <legacyModeNS>true</legacyModeNS>
        </plugin>
    </gazebo>
    <gazebo>
        <plugin filename="libhector_gazebo_ros_imu.so" name="imu_controller">
            <robotNamespace>/</robotNamespace>
            <updateRate>50.0</updateRate>
            <bodyName>base_link</bodyName>
            <topicName>imu/data</topicName>
            <accelDrift>0.005 0.005 0.005</accelDrift>
            <accelGaussianNoise>0.005 0.005 0.005</accelGaussianNoise>
            <rateDrift>0.005 0.005 0.005</rateDrift>
            <rateGaussianNoise>0.005 0.005 0.005</rateGaussianNoise>
            <headingDrift>0.005</headingDrift>
            <headingGaussianNoise>0.005</headingGaussianNoise>
        </plugin>
    </gazebo>
    <gazebo>
        <plugin filename="libhector_gazebo_ros_gps.so" name="gps_controller">
            <robotNamespace>/</robotNamespace>
            <updateRate>40</updateRate>
            <bodyName>base_link</bodyName>
            <frameId>base_link</frameId>
            <topicName>navsat/fix</topicName>
            <velocityTopicName>navsat/vel</velocityTopicName>
            <referenceLatitude>49.9</referenceLatitude>
            <referenceLongitude>8.9</referenceLongitude>
            <referenceHeading>90</referenceHeading>
            <referenceAltitude>0</referenceAltitude>
            <drift>0.0001 0.0001 0.0001</drift>
        </plugin>
    </gazebo>
    <!-- Run the macros -->
    <link name="kinova_arm_base_link">
        <inertial>
            <origin rpy="0 0 0" xyz="0.00244324 0.00015573 0.08616742" />
            <mass value="1.14608471" />
            <inertia ixx="0.00335854" ixy="3.9E-07" ixz="0.00010989" iyy="0.003311" iyz="1.91E-06" izz="0.00077158" />
        </inertial>
        <visual>
            <origin rpy="0 0 0" xyz="0 0 0" />
            <geometry>
                <mesh filename="package://kortex_description/arms/gen3_lite/6dof/meshes/base_link.STL" />
            </geometry>
            <material name="">
                <color rgba="0.803 0.824 0.820 1" />
            </material>
        </visual>
        <collision>
            <origin rpy="0 0 0" xyz="0 0 0" />
            <geometry>
                <mesh filename="package://kortex_description/arms/gen3_lite/6dof/meshes/base_link.STL" />
            </geometry>
        </collision>
    </link>
    <gazebo reference="kinova_arm_base_link">
        <material>Kortex/Gray</material>
    </gazebo>
    <link name="kinova_arm_shoulder_link">
        <inertial>
            <origin rpy="0 0 0" xyz="2.477E-05 0.02213531 0.09937686" />
            <mass value="0.95974404" />
            <inertia ixx="0.00165947" ixy="2E-08" ixz="3.6E-07" iyy="0.00140355" iyz="0.00034927" izz="0.00089493" />
        </inertial>
        <visual>
            <origin rpy="0 0 0" xyz="0 0 0" />
            <geometry>
                <mesh filename="package://kortex_description/arms/gen3_lite/6dof/meshes/shoulder_link.STL" />
            </geometry>
            <material name="">
                <color rgba="0.803 0.824 0.820 1" />
            </material>
        </visual>
        <collision>
            <origin rpy="0 0 0" xyz="0 0 0" />
            <geometry>
                <mesh filename="package://kortex_description/arms/gen3_lite/6dof/meshes/shoulder_link.STL" />
            </geometry>
        </collision>
    </link>
    <gazebo reference="kinova_arm_shoulder_link">
        <material>Kortex/Gray</material>
    </gazebo>
    <joint name="kinova_arm_joint_1" type="revolute">
        <origin rpy="0 0 0" xyz="0 0 0.12825" />
        <parent link="kinova_arm_base_link" />
        <child link="kinova_arm_shoulder_link" />
        <axis xyz="0 0 1" />
        <limit effort="10" lower="-2.68" upper="2.68" velocity="1.6" />
    </joint>
    <link name="kinova_arm_arm_link">
        <inertial>
            <origin rpy="0 0 0" xyz="0.02998299 0.21154808 0.0453031" />
            <mass value="1.17756164" />
            <inertia ixx="0.01149277" ixy="1E-06" ixz="1.6E-07" iyy="0.00102851" iyz="0.00140765" izz="0.01133492" />
        </inertial>
        <visual>
            <origin rpy="0 0 0" xyz="0 0 0" />
            <geometry>
                <mesh filename="package://kortex_description/arms/gen3_lite/6dof/meshes/arm_link.STL" />
            </geometry>
            <material name="">
                <color rgba="0.803 0.824 0.820 1" />
            </material>
        </visual>
        <collision>
            <origin rpy="0 0 0" xyz="0 0 0" />
            <geometry>
                <mesh filename="package://kortex_description/arms/gen3_lite/6dof/meshes/arm_link.STL" />
            </geometry>
        </collision>
    </link>
    <gazebo reference="kinova_arm_arm_link">
        <material>Kortex/Gray</material>
    </gazebo>
    <joint name="kinova_arm_joint_2" type="revolute">
        <origin rpy="1.5708 0 0" xyz="0 -0.03 0.115" />
        <parent link="kinova_arm_shoulder_link" />
        <child link="kinova_arm_arm_link" />
        <axis xyz="0 0 1" />
        <limit effort="14" lower="-2.61" upper="2.61" velocity="1.6" />
    </joint>
    <link name="kinova_arm_forearm_link">
        <inertial>
            <origin rpy="0 0 0" xyz="0.0301559 0.09502206 0.0073555" />
            <mass value="0.59767669" />
            <inertia ixx="0.00163256" ixy="7.11E-06" ixz="1.54E-06" iyy="0.00029798" iyz="9.587E-05" izz="0.00169091" />
        </inertial>
        <visual>
            <origin rpy="0 0 0" xyz="0 0 0" />
            <geometry>
                <mesh filename="package://kortex_description/arms/gen3_lite/6dof/meshes/forearm_link.STL" />
            </geometry>
            <material name="">
                <color rgba="0.803 0.824 0.820 1" />
            </material>
        </visual>
        <collision>
            <origin rpy="0 0 0" xyz="0 0 0" />
            <geometry>
                <mesh filename="package://kortex_description/arms/gen3_lite/6dof/meshes/forearm_link.STL" />
            </geometry>
        </collision>
    </link>
    <gazebo reference="kinova_arm_forearm_link">
        <material>Kortex/Gray</material>
    </gazebo>
    <joint name="kinova_arm_joint_3" type="revolute">
        <origin rpy="-3.1416 0 0" xyz="0 0.28 0" />
        <parent link="kinova_arm_arm_link" />
        <child link="kinova_arm_forearm_link" />
        <axis xyz="0 0 1" />
        <limit effort="10" lower="-2.61" upper="2.61" velocity="1.6" />
    </joint>
    <link name="kinova_arm_lower_wrist_link">
        <inertial>
            <origin rpy="0 0 0" xyz="0.00575149 0.01000443 0.08719207" />
            <mass value="0.52693412" />
            <inertia ixx="0.00069098" ixy="2.4E-07" ixz="0.00016483" iyy="0.00078519" iyz="7.4E-07" izz="0.00034115" />
        </inertial>
        <visual>
            <origin rpy="0 0 0" xyz="0 0 0" />
            <geometry>
                <mesh filename="package://kortex_description/arms/gen3_lite/6dof/meshes/lower_wrist_link.STL" />
            </geometry>
            <material name="">
                <color rgba="0.803 0.824 0.820 1" />
            </material>
        </visual>
        <collision>
            <origin rpy="0 0 0" xyz="0 0 0" />
            <geometry>
                <mesh filename="package://kortex_description/arms/gen3_lite/6dof/meshes/lower_wrist_link.STL" />
            </geometry>
        </collision>
    </link>
    <gazebo reference="kinova_arm_lower_wrist_link">
        <material>Kortex/Gray</material>
    </gazebo>
    <joint name="kinova_arm_joint_4" type="revolute">
        <origin rpy="1.5708 0 0" xyz="0 -0.14 0.02" />
        <parent link="kinova_arm_forearm_link" />
        <child link="kinova_arm_lower_wrist_link" />
        <axis xyz="0 0 1" />
        <limit effort="7" lower="-2.6" upper="2.6" velocity="1.6" />
    </joint>
    <link name="kinova_arm_upper_wrist_link">
        <inertial>
            <origin rpy="0 0 0" xyz="0.08056517 0.00980409 0.01872799" />
            <mass value="0.58097325" />
            <inertia ixx="0.00021268" ixy="5.21E-06" ixz="2.91E-06" iyy="0.00106371" iyz="1.1E-07" izz="0.00108465" />
        </inertial>
        <visual>
            <origin rpy="0 0 0" xyz="0 0 0" />
            <geometry>
                <mesh filename="package://kortex_description/arms/gen3_lite/6dof/meshes/upper_wrist_link.STL" />
            </geometry>
            <material name="">
                <color rgba="0.803 0.824 0.820 1" />
            </material>
        </visual>
        <collision>
            <origin rpy="0 0 0" xyz="0 0 0" />
            <geometry>
                <mesh filename="package://kortex_description/arms/gen3_lite/6dof/meshes/upper_wrist_link.STL" />
            </geometry>
        </collision>
    </link>
    <gazebo reference="kinova_arm_upper_wrist_link">
        <material>Kortex/Gray</material>
    </gazebo>
    <joint name="kinova_arm_joint_5" type="revolute">
        <origin rpy="0 1.5708 0" xyz="0.0285 0 0.105" />
        <parent link="kinova_arm_lower_wrist_link" />
        <child link="kinova_arm_upper_wrist_link" />
        <axis xyz="0 0 1" />
        <limit effort="7" lower="-2.53" upper="2.53" velocity="1.6" />
    </joint>
    <link name="kinova_arm_end_effector_link" />
    <joint name="kinova_arm_joint_6" type="revolute">
        <origin rpy="0 -1.5708 0" xyz="-0.105 0 0.0285" />
        <parent link="kinova_arm_upper_wrist_link" />
        <child link="kinova_arm_end_effector_link" />
        <axis xyz="0 0 1" />
        <limit effort="7" lower="-2.6" upper="2.6" velocity="3.2" />
    </joint>
    <link name="kinova_arm_dummy_link" />
    <joint name="kinova_arm_end_effector" type="fixed">
        <origin rpy="0 0 0" xyz="0 0 0" />
        <parent link="kinova_arm_end_effector_link" />
        <child link="kinova_arm_dummy_link" />
        <axis xyz="0 0 1" />
        <limit effort="0" lower="0" upper="0" velocity="0" />
    </joint>
    <!-- Tool frame used by the arm -->
    <link name="kinova_arm_tool_frame" />
    <joint name="kinova_arm_tool_frame_joint" type="fixed">
        <origin rpy="0 0 1.57079632679" xyz="0 0 0.130" />
        <parent link="kinova_arm_dummy_link" />
        <child link="kinova_arm_tool_frame" />
        <axis xyz="0 0 0" />
    </joint>
    <!-- Gripper description -->
    <joint name="kinova_arm_gripper_base_joint" type="fixed">
        <origin rpy="0 0 0" xyz="0 0 0" />
        <parent link="kinova_arm_dummy_link" />
        <child link="kinova_arm_gripper_base_link" />
        <axis xyz="0 0 0" />
    </joint>
    <link name="kinova_arm_gripper_base_link">
        <inertial>
            <origin rpy="0 0 0" xyz="4.03E-06 1.08E-05 0.041397" />
            <mass value="0.1395" />
            <inertia ixx="0.00011614" ixy="1E-08" ixz="4E-08" iyy="0.00010327" iyz="0" izz="9.707E-05" />
        </inertial>
        <visual>
            <origin rpy="0 0 0" xyz="0 0 0" />
            <geometry>
                <mesh filename="package://kortex_description/grippers/gen3_lite_2f/meshes/gripper_base_link.STL" />
            </geometry>
            <material name="">
                <color rgba="0.803 0.824 0.820 1" />
            </material>
        </visual>
        <collision>
            <origin rpy="0 0 0" xyz="0 0 0" />
            <geometry>
                <mesh filename="package://kortex_description/grippers/gen3_lite_2f/meshes/gripper_base_link.STL" />
            </geometry>
        </collision>
    </link>
    <gazebo reference="kinova_arm_gripper_base_link">
        <material>Kortex/Gray</material>
    </gazebo>
    <link name="kinova_arm_right_finger_prox_link">
        <inertial>
            <origin rpy="0 0 0" xyz="0.020257 0.0063483 6.991E-05" />
            <mass value="0.018385" />
            <inertia ixx="2.29E-06" ixy="1.43E-06" ixz="0" iyy="4.56E-06" iyz="0" izz="4.77E-06" />
        </inertial>
        <visual>
            <origin rpy="0 0 0" xyz="0 0 0" />
            <geometry>
                <mesh filename="package://kortex_description/grippers/gen3_lite_2f/meshes/right_finger_prox_link.STL" />
            </geometry>
            <material name="">
                <color rgba="0.803 0.824 0.820 1" />
            </material>
        </visual>
        <collision>
            <origin rpy="0 0 0" xyz="0 0 0" />
            <geometry>
                <mesh filename="package://kortex_description/grippers/gen3_lite_2f/meshes/right_finger_prox_link.STL" />
            </geometry>
        </collision>
    </link>
    <gazebo reference="kinova_arm_right_finger_prox_link">
        <material>Kortex/Gray</material>
    </gazebo>
    <joint name="kinova_arm_right_finger_bottom_joint" type="revolute">
        <origin rpy="0 1.5708 0" xyz="0 -0.030501 0.070003" />
        <parent link="kinova_arm_gripper_base_link" />
        <child link="kinova_arm_right_finger_prox_link" />
        <axis xyz="0 0 1" />
        <limit effort="1000" lower="-0.09" upper="0.96" velocity="0.6" />
    </joint>
    <link name="kinova_arm_right_finger_dist_link">
        <inertial>
            <origin rpy="0 0 0" xyz="0.018488 0.0011091 0" />
            <mass value="0.010748" />
            <inertia ixx="6.3E-07" ixy="3.2E-07" ixz="0" iyy="1.83E-06" iyz="0" izz="1.61E-06" />
        </inertial>
        <visual>
            <origin rpy="0 0 0" xyz="0 0 0" />
            <geometry>
                <mesh filename="package://kortex_description/grippers/gen3_lite_2f/meshes/right_finger_dist_link.STL" />
            </geometry>
            <material name="">
                <color rgba="0 0.055 0.525 1" />
            </material>
        </visual>
        <collision>
            <origin rpy="0 0 0" xyz="0 0 0" />
            <geometry>
                <mesh filename="package://kortex_description/grippers/gen3_lite_2f/meshes/right_finger_dist_link.STL" />
            </geometry>
        </collision>
    </link>
    <gazebo reference="kinova_arm_right_finger_dist_link">
        <material>Kortex/Blue</material>
    </gazebo>
    <joint name="kinova_arm_right_finger_tip_joint" type="revolute">
        <origin rpy="0 0 0" xyz="-0.045636 0.020423 0" />
        <parent link="kinova_arm_right_finger_prox_link" />
        <child link="kinova_arm_right_finger_dist_link" />
        <axis xyz="0 0 1" />
        <limit effort="1000" lower="-0.50" upper="0.21" velocity="1000" />
        <!--limit lower="-1.03" upper="0.21" effort="1000" velocity="1000" /-->
        <mimic joint="kinova_arm_right_finger_bottom_joint" multiplier="-0.676" offset="0.149" />
    </joint>
    <link name="kinova_arm_left_finger_prox_link">
        <inertial>
            <origin rpy="0 0 0" xyz="0.020257 0.0063483 6.99E-05" />
            <mass value="0.018385" />
            <inertia ixx="2.29E-06" ixy="1.43E-06" ixz="0" iyy="4.56E-06" iyz="0" izz="4.77E-06" />
        </inertial>
        <visual>
            <origin rpy="0 0 0" xyz="0 0 0" />
            <geometry>
                <mesh filename="package://kortex_description/grippers/gen3_lite_2f/meshes/left_finger_prox_link.STL" />
            </geometry>
            <material name="">
                <color rgba="0.803 0.824 0.820 1" />
            </material>
        </visual>
        <collision>
            <origin rpy="0 0 0" xyz="0 0 0" />
            <geometry>
                <mesh filename="package://kortex_description/grippers/gen3_lite_2f/meshes/left_finger_prox_link.STL" />
            </geometry>
        </collision>
    </link>
    <gazebo reference="kinova_arm_left_finger_prox_link">
        <material>Kortex/Gray</material>
    </gazebo>
    <joint name="kinova_arm_left_finger_bottom_joint" type="revolute">
        <origin rpy="0 1.5708 0" xyz="0 0.0305 0.070003" />
        <parent link="kinova_arm_gripper_base_link" />
        <child link="kinova_arm_left_finger_prox_link" />
        <axis xyz="0 0 1" />
        <limit effort="1000" lower="-0.96" upper="0.09" velocity="1000" />
        <mimic joint="kinova_arm_right_finger_bottom_joint" multiplier="-1.0" offset="0.0" />
    </joint>
    <link name="kinova_arm_left_finger_dist_link">
        <inertial>
            <origin rpy="0 0 0" xyz="-0.018488 0.0011091 0" />
            <mass value="0.010748" />
            <inertia ixx="6.3E-07" ixy="3.2E-07" ixz="0" iyy="1.83E-06" iyz="0" izz="1.61E-06" />
        </inertial>
        <visual>
            <origin rpy="0 0 0" xyz="0 0 0" />
            <geometry>
                <mesh filename="package://kortex_description/grippers/gen3_lite_2f/meshes/left_finger_dist_link.STL" />
            </geometry>
            <material name="">
                <color rgba="0 0.055 0.525 1" />
            </material>
        </visual>
        <collision>
            <origin rpy="0 0 0" xyz="0 0 0" />
            <geometry>
                <mesh filename="package://kortex_description/grippers/gen3_lite_2f/meshes/left_finger_dist_link.STL" />
            </geometry>
        </collision>
    </link>
    <gazebo reference="kinova_arm_left_finger_dist_link">
        <material>Kortex/Blue</material>
    </gazebo>
    <joint name="kinova_arm_left_finger_tip_joint" type="revolute">
        <origin rpy="0 0 0" xyz="-0.045636 -0.020423 6.9901E-05" />
        <parent link="kinova_arm_left_finger_prox_link" />
        <child link="kinova_arm_left_finger_dist_link" />
        <axis xyz="0 0 -1" />
        <limit effort="1000" lower="-0.50" upper="0.21" velocity="1000" />
        <!--limit lower="-1.03" upper="0.21" effort="1000" velocity="1000" /-->
        <mimic joint="kinova_arm_right_finger_bottom_joint" multiplier="-0.676" offset="0.149" />
    </joint>
    <joint name="arm_mount_joint" type="fixed">
        <origin rpy="0.0 0.0 0.0" xyz="0.0 0.0 0.042" />
        <parent link="top_plate_front_link" />
        <child link="kinova_arm_base_link" />
    </joint>
    <!-- This file is a placeholder which is included by default from
       husky.urdf.xacro. If a robot is being customized and requires
       additional URDF, set the HUSKY_URDF_EXTRAS environment variable
       to the full path of the file you would like included. -->
    <transmission name="trans_kinova_arm_joint_1">
        <type>transmission_interface/SimpleTransmission</type>
        <joint name="kinova_arm_joint_1">
            <hardwareInterface>hardware_interface/EffortJointInterface</hardwareInterface>
        </joint>
        <actuator name="kinova_arm_joint_1_motor">
            <hardwareInterface>hardware_interface/EffortJointInterface</hardwareInterface>
            <mechanicalReduction>1</mechanicalReduction>
        </actuator>
    </transmission>
    <transmission name="trans_kinova_arm_joint_2">
        <type>transmission_interface/SimpleTransmission</type>
        <joint name="kinova_arm_joint_2">
            <hardwareInterface>hardware_interface/EffortJointInterface</hardwareInterface>
        </joint>
        <actuator name="kinova_arm_joint_2_motor">
            <hardwareInterface>hardware_interface/EffortJointInterface</hardwareInterface>
            <mechanicalReduction>1</mechanicalReduction>
        </actuator>
    </transmission>
    <transmission name="trans_kinova_arm_joint_3">
        <type>transmission_interface/SimpleTransmission</type>
        <joint name="kinova_arm_joint_3">
            <hardwareInterface>hardware_interface/EffortJointInterface</hardwareInterface>
        </joint>
        <actuator name="kinova_arm_joint_3_motor">
            <hardwareInterface>hardware_interface/EffortJointInterface</hardwareInterface>
            <mechanicalReduction>1</mechanicalReduction>
        </actuator>
    </transmission>
    <transmission name="trans_kinova_arm_joint_4">
        <type>transmission_interface/SimpleTransmission</type>
        <joint name="kinova_arm_joint_4">
            <hardwareInterface>hardware_interface/EffortJointInterface</hardwareInterface>
        </joint>
        <actuator name="kinova_arm_joint_4_motor">
            <hardwareInterface>hardware_interface/EffortJointInterface</hardwareInterface>
            <mechanicalReduction>1</mechanicalReduction>
        </actuator>
    </transmission>
    <transmission name="trans_kinova_arm_joint_5">
        <type>transmission_interface/SimpleTransmission</type>
        <joint name="kinova_arm_joint_5">
            <hardwareInterface>hardware_interface/EffortJointInterface</hardwareInterface>
        </joint>
        <actuator name="kinova_arm_joint_5_motor">
            <hardwareInterface>hardware_interface/EffortJointInterface</hardwareInterface>
            <mechanicalReduction>1</mechanicalReduction>
        </actuator>
    </transmission>
    <transmission name="trans_kinova_arm_joint_6">
        <type>transmission_interface/SimpleTransmission</type>
        <joint name="kinova_arm_joint_6">
            <hardwareInterface>hardware_interface/EffortJointInterface</hardwareInterface>
        </joint>
        <actuator name="kinova_arm_joint_6_motor">
            <hardwareInterface>hardware_interface/EffortJointInterface</hardwareInterface>
            <mechanicalReduction>1</mechanicalReduction>
        </actuator>
    </transmission>
    <transmission name="trans_kinova_arm_right_finger_bottom_joint">
        <type>transmission_interface/SimpleTransmission</type>
        <joint name="kinova_arm_right_finger_bottom_joint">
            <hardwareInterface>hardware_interface/EffortJointInterface</hardwareInterface>
        </joint>
        <actuator name="kinova_arm_right_finger_bottom_joint_motor">
            <hardwareInterface>hardware_interface/EffortJointInterface</hardwareInterface>
            <mechanicalReduction>1</mechanicalReduction>
        </actuator>
    </transmission>
    <transmission name="trans_kinova_arm_right_finger_tip_joint">
        <type>transmission_interface/SimpleTransmission</type>
        <joint name="kinova_arm_right_finger_tip_joint">
            <hardwareInterface>hardware_interface/EffortJointInterface</hardwareInterface>
        </joint>
        <actuator name="kinova_arm_right_finger_tip_joint_motor">
            <hardwareInterface>hardware_interface/EffortJointInterface</hardwareInterface>
            <mechanicalReduction>1</mechanicalReduction>
        </actuator>
    </transmission>
    <transmission name="trans_kinova_arm_left_finger_bottom_joint">
        <type>transmission_interface/SimpleTransmission</type>
        <joint name="kinova_arm_left_finger_bottom_joint">
            <hardwareInterface>hardware_interface/EffortJointInterface</hardwareInterface>
        </joint>
        <actuator name="kinova_arm_left_finger_bottom_joint_motor">
            <hardwareInterface>hardware_interface/EffortJointInterface</hardwareInterface>
            <mechanicalReduction>1</mechanicalReduction>
        </actuator>
    </transmission>
    <transmission name="trans_kinova_arm_left_finger_tip_joint">
        <type>transmission_interface/SimpleTransmission</type>
        <joint name="kinova_arm_left_finger_tip_joint">
            <hardwareInterface>hardware_interface/EffortJointInterface</hardwareInterface>
        </joint>
        <actuator name="kinova_arm_left_finger_tip_joint_motor">
            <hardwareInterface>hardware_interface/EffortJointInterface</hardwareInterface>
            <mechanicalReduction>1</mechanicalReduction>
        </actuator>
    </transmission>
</robot>

